Workbook

Sheet 00_Lecture
A1: TAQADDUM — Référentiel de 43 KPI (version recentrée)
A3: Version | B3: v1 — 12/10/2026 — remplace le classeur « 55 KPI » (voir feuille 07_Correspondance).
A4: Source | B4: Fiches projets CNED — situation arrêtée au 30 juin 2025 (51 projets, 6 538,322 Md DA) et critique du classeur précédent.
A5: Principe | B5: 43 KPI répartis en 9 familles (AV, FI, DL, BU, QR, DO, PP, CO, GV). L'acteur concerné est un filtre (colonnes Alimenté_par et Responsable), pas un axe de classement.
A7: IMPORTANCE | B7: Lettre indiquant le rôle du KPI dans le dispositif (colonne D de 01_KPI). Elle est indépendante de la phase de déploiement.
A8: [M] Obligatoire | B8: Indispensable : socle du suivi, à afficher dans toute vue, à produire dès le pilote. 20 KPI.
A9: [A] Avancé | B9: Complémentaire : approfondit l'analyse ; nécessite souvent des données de détail (MO, BET, terrain). 14 KPI.
A10: [S] Stratégique | B10: Décision et pilotage : synthèses et prévisions pour la direction (arbitrage de financement, sort d'un contractant, vue portefeuille). 9 KPI.
A12: PHASE | B12: MVP = calculable ou saisissable dès le pilote. V2 = après le pilote (saisie MO, BET ou terrain). Vision = hors pilote, aucune donnée disponible dans les fiches CNED.
A13: CALCULABILITÉ | B13: Évaluée par rapport au PDF des fiches CNED : « Calculable sur fiches CNED », « Partiel (extraction texte) », « Saisie requise », « Calculable par la plateforme ».
A15: RÈGLES COMMUNES
A16: Projet actif | B16: Projet ni achevé ni réceptionné. Sur le PDF : 46 projets (38 en cours + 8 en voie d'achèvement).
A17: Deux délais | B17: Le délai initial et le délai en vigueur (après avenants) sont toujours conservés ; la consommation du délai n'est jamais plafonnée à 100 %.
A18: AE de référence | B18: AE actuelle approuvée. L'AE initiale est ajustée des transferts de maîtrise d'ouvrage ou de périmètre. L'AE déléguée est distinguée de l'AE totale.
A19: TAP consolidé | B19: Avancement valorisé de tous les marchés du projet, y compris marchés résiliés et marchés de parachèvement. Les avances forfaitaires sont comptées à part.
A20: Seuils | B20: Numériques (colonnes K et L) : Vert si « plus haut = mieux » ≥ Seuil_Vert ; Orange si ≥ Seuil_Rouge ; Rouge sinon. Pour « plus bas = mieux » : Vert ≤ Seuil_Vert ; Orange ≤ Seuil_Rouge ; Rouge au-delà. « Écart absolu » : même règle sur la valeur absolue. Les bornes sont incluses côté meilleur niveau. Les règles spéciales et KPI d'information n'ont pas de seuil numérique.
A21: ⚠ Seuils provisoires | B21: Les seuils sont des propositions TAQADDUM, ni officiels CNED ni validés. À recalibrer sur 12–24 mois d'historique. Les pondérations de CO1 et CO6 sont également provisoires et à valider en équipe.
A22: Langage | B22: Les acronymes techniques (EVM, CPI, SPI) ne sont pas exposés aux utilisateurs non spécialistes ; les définitions de la colonne G sont rédigées en langage courant.
A24: FEUILLES | B24: 01_KPI : référentiel complet · 02_Regles_Alertes : 17 règles d'alerte reliées aux KPI · 03_Matrice_Roles : qui voit quoi (R/S/V) · 04_Vue_Role : vue personnalisée par rôle (liste déroulante) · 05_Synthese : comptages par famille, importance, phase · 06_Simulateur : test des seuils (formules) · 07_Correspondance : devenir des 55 anciens KPI · 08_Glossaire · 09_Roles_Interfaces : implémentation de chaque rôle dans chaque interface (mode, KPI R/S/V, alertes D/I).
A26: RÔLES | B26: 6 rôles : Direction CNED, CNED/PMO, Maître d'ouvrage, Bureau d'études, Contractant, Contrôleur budgétaire. Droits : R = responsable, S = alimente, V = consulte. Le contractant ne voit que ses propres marchés et jamais les scores d'autres contractants.

Sheet 01_KPI
A1: KPI_ID | B1: Famille | C1: Nom_KPI | D1: Importance | E1: Phase | F1: Calculabilité | G1: Définition | H1: Formule | I1: Unité | J1: Sens | K1: Seuil_Vert | L1: Seuil_Rouge | M1: Vert | N1: Orange | O1: Rouge | P1: Alimenté_par | Q1: Responsable | R1: Fréquence_cible | S1: Tables_sources | T1: Justification_importance
A2: AV1 | B2: AV – Avancement physique | C2: Avancement physique consolidé | D2: [M] | E2: MVP | F2: Partiel | G2: Part des travaux réellement exécutés sur l'ensemble du projet, tous marchés confondus (y compris marchés résiliés et de parachèvement). | H2: Valeur des travaux réalisés ÷ coût total estimé du projet × 100 | I2: % | J2: Information | M2: Information | N2: — | O2: Information | P2: Fiche CNED / MO | Q2: MO | R2: Mensuelle | S2: Projets; Marches; Avancement_Historique | T2: Socle de tout le suivi : sans lui, aucun autre KPI d'avancement n'a de sens.
A3: AV2 | B3: AV – Avancement physique | C3: Indice d'avancement | D3: [M] | E3: MVP | F3: Calculable sur fiches CNED | G3: Compare l'avancement physique au temps déjà consommé ; 1 = projet dans le rythme. | H3: TAP consolidé ÷ % du délai en vigueur consommé | I3: ratio | J3: Plus haut = mieux | K3: 0.9 | L3: 0.7 | M3: ≥ 0.9 ratio | N3: de 0.7 à < 0.9 ratio | O3: < 0.7 ratio | P3: Plateforme | Q3: CNED / PMO | R3: Mensuelle | S3: Projets; Marches | T3: KPI central de détection du retard ; remplace cinq anciens KPI d'avancement absolu.
A4: AV3 | B4: AV – Avancement physique | C4: Cadence récente | D4: [A] | E4: V2 | F4: Saisie requise | G4: Vitesse d'avancement des trois derniers mois comparée à celle nécessaire pour finir dans le délai. | H4: ΔTAP des 3 derniers mois ÷ ΔTAP requis pour finir dans le délai en vigueur | I4: ratio | J4: Plus haut = mieux | K4: 0.9 | L4: 0.7 | M4: ≥ 0.9 ratio | N4: de 0.7 à < 0.9 ratio | O4: < 0.7 ratio | P4: MO / BET | Q4: MO | R4: Mensuelle | S4: Avancement_Historique | T4: Exige un historique mensuel ; utile pour anticiper, pas indispensable au pilote.
A5: AV4 | B5: AV – Avancement physique | C5: Part non contractualisée | D5: [A] | E5: MVP | F5: Partiel (extraction texte) | G5: Part du reste à réaliser pour laquelle aucun marché n'est notifié (lots non lancés, appels d'offres infructueux). | H5: Coût du reste à réaliser sans marché notifié ÷ coût du reste à réaliser × 100 | I5: % | J5: Plus bas = mieux | K5: 10 | L5: 30 | M5: ≤ 10 % | N5: > 10 à 30 % | O5: > 30 % | P5: MO | Q5: MO | R5: Mensuelle | S5: Marches; Projets | T5: Distingue lots non lancés et travaux arrêtés ; affine le diagnostic.
A6: AV5 | B6: AV – Avancement physique | C6: Mise en service fonctionnelle | D6: [S] | E6: MVP | F6: Partiel (extraction texte) | G6: Part des ouvrages mis en service qui fonctionnent pleinement (sans réserve ni lot système, signalisation ou énergie en retard). | H6: Ouvrages mis en service sans réserve ni lot système en retard ÷ ouvrages mis en service × 100 | I6: % | J6: Plus haut = mieux | K6: 90 | L6: 60 | M6: ≥ 90 % | N6: de 60 à < 90 % | O6: < 60 % | P6: CNED / MO | Q6: CNED | R6: Mensuelle | S6: Projets; Marches; Receptions (à créer) | T6: Mesure le service réellement rendu, pas seulement l'avancement des travaux.
A7: FI1 | B7: FI – Finance | C7: Écart physique–financier | D7: [M] | E7: MVP | F7: Calculable sur fiches CNED | G7: Écart entre avancement physique et consommation financière des travaux, hors avances. Positif : retard de paiement ; négatif : paiement en avance du réalisé. | H7: TAP − taux financier travaux hors avances (en points) | I7: pts | J7: Écart absolu | K7: 5 | L7: 10 | M7: |écart| ≤ 5 pts | N7: |écart| > 5 à 10 pts | O7: |écart| > 10 pts | P7: MO / Finance | Q7: MO | R7: Mensuelle | S7: Projets; Marches; Situations_Facturations | T7: Détecte à la fois les retards de paiement et les paiements non adossés à du réalisé.
A8: FI2 | B8: FI – Finance | C8: Couverture du reste à faire | D8: [S] | E8: V2 | F8: Saisie requise | G8: Capacité des ressources financières restantes à couvrir ce qu'il reste à payer, avenants en préparation compris. | H8: (AE actuelle − paiements) ÷ reste à faire estimé × 100 | I8: % | J8: Plus haut = mieux | K8: 100 | L8: 90 | M8: ≥ 100 % | N8: de 90 à < 100 % | O8: < 90 % | P8: MO / Finance | Q8: MO / Finance | R8: Mensuelle | S8: Projets; Reevaluations_AE; AE_Operations (à créer) | T8: Soutient l'arbitrage de financement ; remplace cinq KPI redondants ou contradictoires.
A9: FI3 | B9: FI – Finance | C9: Couverture des crédits de paiement | D9: [S] | E9: V2 | F9: Saisie requise | G9: Les crédits de paiement de l'exercice couvrent-ils les paiements prévus ? (insuffisance des CP : contrainte récurrente.) | H9: CP inscrits de l'exercice ÷ paiements prévus de l'exercice × 100 | I9: % | J9: Plus haut = mieux | K9: 100 | L9: 80 | M9: ≥ 100 % | N9: de 80 à < 100 % | O9: < 80 % | P9: Finance | Q9: Contrôleur budgétaire | R9: Mensuelle | S9: Credits_Paiement (à créer); Planning | T9: Les CP étaient absents de l'ancien modèle alors que le PDF les cite comme contrainte.
A10: FI4 | B10: FI – Finance | C10: Dérive d'AE ajustée | D10: [M] | E10: MVP | F10: Calculable sur fiches CNED | G10: Augmentation de l'AE par rapport à l'AE initiale, après neutralisation des transferts de maîtrise d'ouvrage ou de périmètre. | H10: (AE actuelle − AE initiale ajustée) ÷ AE initiale ajustée × 100 | I10: % | J10: Plus bas = mieux | K10: 20 | L10: 60 | M10: ≤ 20 % | N10: > 20 à 60 % | O10: > 60 % | P10: Fiche CNED | Q10: Contrôleur budgétaire | R10: Mensuelle | S10: Projets; Reevaluations_AE; AE_Operations (à créer) | T10: Mesure du dérapage budgétaire ; remplace trois KPI identiques. Seuils provisoires calés sur le portefeuille.
A11: FI5 | B11: FI – Finance | C11: Réévaluations d'AE en attente | D11: [M] | E11: MVP | F11: Partiel (extraction texte) | G11: Ancienneté de la plus ancienne réévaluation d'AE non encore approuvée ; le montant en attente est affiché à côté. | H11: Date de référence − date de la plus ancienne demande non approuvée (jours) | I11: j | J11: Plus bas = mieux | K11: 60 | L11: 120 | M11: ≤ 60 j | N11: > 60 à 120 j | O11: > 120 j | P11: Fiche CNED | Q11: Contrôleur budgétaire / CNED | R11: Mensuelle | S11: Reevaluations_AE | T11: Les notifications dépendent d'une approbation en réunion de Gouvernement ou Conseil des Ministres : goulot majeur.
A12: FI6 | B12: FI – Finance | C12: Retard de paiement des situations | D12: [A] | E12: V2 | F12: Saisie requise | G12: Ancienneté médiane des situations de travaux reçues mais non payées. | H12: Médiane (date de référence − date de réception) des situations non payées (jours) | I12: j | J12: Plus bas = mieux | K12: 30 | L12: 60 | M12: ≤ 30 j | N12: > 30 à 60 j | O12: > 60 j | P12: MO / Finance | Q12: MO / Finance | R12: Mensuelle | S12: Situations_Facturations | T12: Cause documentée de démobilisation des entreprises ; données hors fiches CNED.
A13: FI7 | B13: FI – Finance | C13: Encours de situations | D13: [A] | E13: V2 | F13: Saisie requise | G13: Poids des situations reçues mais non payées par rapport au montant du marché. | H13: Σ situations reçues non payées ÷ montant du marché × 100 | I13: % | J13: Plus bas = mieux | K13: 5 | L13: 15 | M13: ≤ 5 % | N13: > 5 à 15 % | O13: > 15 % | P13: Contrôleur budgétaire | Q13: Contrôleur budgétaire | R13: Mensuelle | S13: Situations_Facturations; Marches | T13: Complète FI6 en montant ; données hors fiches CNED.
A14: DL1 | B14: DL – Délais | C14: Consommation du délai en vigueur | D14: [M] | E14: MVP | F14: Calculable sur fiches CNED | G14: Part du délai contractuel en vigueur (avenants inclus) déjà écoulée ; non plafonnée à 100 %. | H14: Jours écoulés depuis l'ODS de démarrage ÷ délai en vigueur × 100 | I14: % | J14: Plus bas = mieux | K14: 90 | L14: 100 | M14: ≤ 90 % | N14: > 90 à 100 % | O14: > 100 % | P14: Fiche CNED | Q14: MO | R14: Mensuelle | S14: Marches; ODS | T14: Base du suivi des délais ; indispensable à AV2.
... A24: QR4 | B24: QR – Blocages, qualité, risques | C24: Temps perdu à l'arrêt | D24: [M] | E24: MVP | F24: Partiel (extraction texte) | G24: Part du temps écoulé pendant laquelle le chantier est arrêté (ODS d'arrêt ou arrêt de fait). | H24: Jours d'arrêt ÷ jours écoulés × 100 | I24: % | J24: Plus bas = mieux | K24: 5 | L24: 15 | M24: ≤ 5 % | N24: > 5 à 15 % | O24: > 15 % | P24: MO | Q24: MO | R24: Mensuelle | S24: ODS; Blocages_Institutionnels | T24: Sépare « travaux arrêtés » et « lots non lancés » : distinction clé du portefeuille.
A25: QR5 | B25: QR – Blocages, qualité, risques | C25: Aléas non prévus ouverts | D25: [A] | E25: V2 | F25: Partiel (extraction texte) | G25: Événements imprévus ouverts (glissement de terrain, inondation, géologie). | H25: Nombre d'aléas ouverts et état de la solution | I25: nombre | J25: Règle spéciale | M25: 0 aléa ouvert | N25: ≥ 1 aléa avec solution arrêtée | O25: ≥ 1 aléa sans solution arrêtée | P25: MO / BET | Q25: MO | R25: Mensuelle | S25: Blocages_Institutionnels; Taches_Critiques | T25: Cas particuliers (ex. glissement) ; renforce l'analyse sans être indispensable.
A26: QR6 | B26: QR – Blocages, qualité, risques | C26: Modification de consistance en cours | D26: [A] | E26: V2 | F26: Saisie requise | G26: Indique si la consistance du projet est en cours de modification (signe de maturation insuffisante). | H26: Oui / Non | I26: oui/non | J26: Règle spéciale | M26: Non | N26: — | O26: Oui | P26: BET / MO | Q26: BET / MO | R26: Mensuelle | S26: Projets; Avenants | T26: Drapeau de maturation ; utile surtout en revue technique.
A27: QR7 | B27: QR – Blocages, qualité, risques | C27: Non-conformité critique la plus ancienne | D27: [A] | E27: V2 | F27: Saisie requise | G27: Ancienneté de la non-conformité critique ouverte la plus ancienne. | H27: Date de référence − date de découverte de la NC critique ouverte la plus ancienne (jours) | I27: j | J27: Plus bas = mieux | K27: 15 | L27: 30 | M27: ≤ 15 j | N27: > 15 à 30 j | O27: > 30 j | P27: BET | Q27: BET | R27: Mensuelle | S27: Non_Conformites_BET | T27: Registre de NC absent des fiches CNED ; saisie BET nécessaire.
A28: QR8 | B28: QR – Blocages, qualité, risques | C28: Incidents HSE graves | D28: [A] | E28: Vision | F28: Saisie requise | G28: Nombre d'incidents de sécurité graves sur 12 mois. | H28: Nombre d'incidents graves sur 12 mois | I28: nombre | J28: Règle spéciale | M28: 0 | N28: — | O28: ≥ 1 | P28: BET / HSE | Q28: BET / HSE | R28: Mensuelle + immédiate | S28: HSE_Incidents | T28: Hors périmètre du pilote : aucune donnée dans les fiches CNED.
A29: DO1 | B29: DO – Fiabilité des données | C29: Fraîcheur des données | D29: [M] | E29: MVP | F29: Calculable par la plateforme | G29: Âge de la dernière mise à jour d'un projet comparé à la périodicité attendue. | H29: Âge de la dernière mise à jour ÷ périodicité attendue | I29: ratio | J29: Plus bas = mieux | K29: 1 | L29: 2 | M29: ≤ 1 ratio | N29: > 1 à 2 ratio | O29: > 2 ratio | P29: Plateforme | Q29: PMO | R29: Mensuelle | S29: KPI_Valeurs; Projets | T29: Sans données fraîches, tous les autres KPI sont trompeurs.
A30: DO2 | B30: DO – Fiabilité des données | C30: Complétude | D30: [M] | E30: MVP | F30: Calculable par la plateforme | G30: Part des champs obligatoires renseignés. | H30: Champs obligatoires renseignés ÷ champs requis × 100 | I30: % | J30: Plus haut = mieux | K30: 90 | L30: 70 | M30: ≥ 90 % | N30: de 70 à < 90 % | O30: < 70 % | P30: Plateforme | Q30: PMO | R30: Mensuelle | S30: Toutes tables | T30: Rend visible ce qui manque plutôt que de le masquer.
A31: DO3 | B31: DO – Fiabilité des données | C31: Cohérence | D31: [M] | E31: MVP | F31: Calculable par la plateforme | G31: Part des projets présentant au moins une anomalie détectée automatiquement (TAP > 100 %, paiements > engagements, dates incohérentes). | H31: Projets avec ≥ 1 anomalie ÷ projets × 100 | I31: % | J31: Plus bas = mieux | K31: 5 | L31: 20 | M31: ≤ 5 % | N31: > 5 à 20 % | O31: > 20 % | P31: Plateforme | Q31: PMO | R31: Mensuelle | S31: Projets; Marches | T31: Contrôle de qualité minimal avant toute présentation au CNED.
A32: PP1 | B32: PP – Terrain (planification fiable) | C32: Fiabilité du planning hebdomadaire | D32: [A] | E32: V2 | F32: Saisie requise | G32: Part des tâches planifiées de la semaine réellement terminées (PPC). | H32: Tâches terminées ÷ tâches planifiées × 100 | I32: % | J32: Plus haut = mieux | K32: 80 | L32: 60 | M32: ≥ 80 % | N32: de 60 à < 80 % | O32: < 60 % | P32: Terrain / entreprise | Q32: MO | R32: Hebdomadaire | S32: Taches_Critiques; Planning | T32: Cœur de la logique terrain, mais saisie hebdomadaire hors fiches CNED.
A33: PP2 | B33: PP – Terrain (planification fiable) | C33: Mobilisation effective | D33: [A] | E33: V2 | F33: Saisie requise | G33: Moyens (heures, main-d'œuvre, matériel) effectivement mobilisés par rapport au plan. | H33: Moyens effectifs ÷ moyens planifiés × 100 | I33: % | J33: Plus haut = mieux | K33: 90 | L33: 70 | M33: ≥ 90 % | N33: de 70 à < 90 % | O33: < 70 % | P33: Entreprise | Q33: MO | R33: Hebdomadaire | S33: Moyens_Mobilises | T33: La « faible mobilisation des moyens » est citée dans une dizaine de fiches.
A34: PP3 | B34: PP – Terrain (planification fiable) | C34: Causes de non-réalisation externes | D34: [A] | E34: V2 | F34: Saisie requise | G34: Répartition des non-réalisations dues à l'emprise, au paiement, aux matériaux ou aux réseaux. | H34: Non-réalisations d'origine externe par cause ÷ total des non-réalisations | I34: % | J34: Information | M34: Information | N34: — | O34: Information | P34: Terrain | Q34: MO | R34: Hebdomadaire | S34: Taches_Critiques | T34: Pareto des causes : prépare l'escalade vers les bons responsables.
A35: CO1 | B35: CO – Contractants et portefeuille | C35: Santé du contractant (0–100) | D35: [S] | E35: MVP | F35: Partiel (poids à valider) | G35: Note synthétique de fiabilité d'un contractant ou groupement. | H35: 40 % AV2 (plafonné à 1) + 25 % inverse de BU1 + 20 % PP2 + 15 % historique de résiliations ; si PP2 absent, ses 20 % sont redistribués (poids provisoires) | I35: 0–100 | J35: Plus haut = mieux | K35: 75 | L35: 50 | M35: ≥ 75 0–100 | N35: de 50 à < 75 0–100 | O35: < 50 0–100 | P35: CNED / MO | Q35: CNED | R35: Mensuelle | S35: Scoring_Contractants; Groupements (à créer); Marches | T35: Aide à décider de la suite donnée à un contractant ; poids à valider en équipe.
A36: CO2 | B36: CO – Contractants et portefeuille | C36: Concentration par contractant | D36: [S] | E36: V2 | F36: Partiel (groupements à modéliser) | G36: Part de l'AE en cours confiée à un même contractant ou groupement. | H36: AE en cours confiée à un contractant ÷ AE en cours × 100 | I36: % | J36: Plus bas = mieux | K36: 15 | L36: 25 | M36: ≤ 15 % | N36: > 15 à 25 % | O36: > 25 % | P36: CNED | Q36: CNED | R36: Mensuelle | S36: Marches; Groupements (à créer) | T36: Risque systémique ; le portefeuille montre une forte concentration.
A37: CO3 | B37: CO – Contractants et portefeuille | C37: Part en parachèvement après résiliation | D37: [S] | E37: MVP | F37: Partiel (extraction texte) | G37: Part de l'AE des projets actifs dont le marché initial a été résilié. | H37: AE des projets dont le marché initial est résilié ÷ AE des projets actifs × 100 | I37: % | J37: Plus bas = mieux | K37: 5 | L37: 15 | M37: ≤ 5 % | N37: > 5 à 15 % | O37: > 15 % | P37: CNED | Q37: CNED | R37: Mensuelle | S37: Marches; Projets | T37: Mesure l'ampleur des défaillances contractuelles à l'échelle du portefeuille.
A38: CO4 | B38: CO – Contractants et portefeuille | C38: Projets en retard important | D38: [M] | E38: MVP | F38: Calculable sur fiches CNED | G38: Part des projets actifs dont le délai est dépassé et l'avancement insuffisant. | H38: Projets avec DL1 > 100 % et AV2 < 0,90 ÷ projets actifs × 100 | I38: % | J38: Plus bas = mieux | K38: 15 | L38: 35 | M38: ≤ 15 % | N38: > 15 à 35 % | O38: > 35 % | P38: Plateforme | Q38: CNED | R38: Mensuelle | S38: Projets; Marches | T38: Donne une définition opérationnelle à « retard important ».
A39: CO5 | B39: CO – Contractants et portefeuille | C39: Projets à l'arrêt | D39: [M] | E39: MVP | F39: Partiel (extraction texte) | G39: Part des projets actifs à l'arrêt (ODS d'arrêt ou arrêt de fait) depuis plus de 60 jours. | H39: Projets arrêtés > 60 jours ÷ projets actifs × 100 | I39: % | J39: Plus bas = mieux | K39: 5 | L39: 15 | M39: ≤ 5 % | N39: > 5 à 15 % | O39: > 15 % | P39: CNED | Q39: CNED | R39: Mensuelle + immédiate | S39: ODS; Projets | T39: Alerte portefeuille de premier niveau.
A40: CO6 | B40: CO – Contractants et portefeuille | C40: Score de santé du portefeuille | D40: [S] | E40: V2 | F40: Partiel (poids à valider) | G40: Note synthétique de l'état du portefeuille, pondérée par l'AE. | H40: 25 % AV2 + 20 % délais (DL1, DL3) + 20 % finance (FI2, FI6) + 20 % blocages (QR1 à QR4) + 15 % CO1 (pondéré AE ; poids provisoires) | I40: 0–100 | J40: Plus haut = mieux | K40: 75 | L40: 55 | M40: ≥ 75 0–100 | N40: de 55 à < 75 0–100 | O40: < 55 0–100 | P40: Plateforme | Q40: CNED / PMO | R40: Mensuelle | S40: Tous KPI de projet | T40: Vue de pilotage ; ne doit être publiée qu'après validation des poids.
A41: GV1 | B41: GV – Gouvernance | C41: Blocages avec responsable et échéance | D41: [M] | E41: MVP | F41: Saisie requise | G41: Part des blocages ouverts ayant un responsable nommé et une date cible. | H41: Blocages ouverts avec responsable et échéance ÷ blocages ouverts × 100 | I41: % | J41: Plus haut = mieux | K41: 90 | L41: 70 | M41: ≥ 90 % | N41: de 70 à < 90 % | O41: < 70 % | P41: CNED / PMO | Q41: CNED / PMO | R41: Mensuelle | S41: Blocages_Institutionnels | T41: Sans responsable, un blocage ne se débloque pas.
A42: GV2 | B42: GV – Gouvernance | C42: Avenants en attente de visa (CSM) | D42: [M] | E42: MVP | F42: Partiel (extraction texte) | G42: Ancienneté de l'avenant le plus ancien non visé par la Commission sectorielle des marchés ; le nombre est affiché à côté. | H42: Date de référence − date de dépôt de l'avenant non visé le plus ancien (jours) | I42: j | J42: Plus bas = mieux | K42: 60 | L42: 120 | M42: ≤ 60 j | N42: > 60 à 120 j | O42: > 120 j | P42: MO / CNED | Q42: MO / CNED | R42: Mensuelle | S42: Avenants | T42: Goulot documenté dans le PDF (visa avec réserves, ajournements).
A43: GV3 | B43: GV – Gouvernance | C43: Arbitrages échus | D43: [A] | E43: V2 | F43: Saisie requise | G43: Part des projets actifs avec un arbitrage ayant dépassé son échéance. | H43: Projets avec arbitrage échu ÷ projets actifs × 100 | I43: % | J43: Plus bas = mieux | K43: 10 | L43: 25 | M43: ≤ 10 % | N43: > 10 à 25 % | O43: > 25 % | P43: CNED | Q43: CNED | R43: Mensuelle | S43: Decisions_Arbitrages | T43: Utile quand le registre de décisions sera alimenté.
A44: GV4 | B44: GV – Gouvernance | C44: Réceptions en attente | D44: [A] | E44: MVP | F44: Partiel (extraction texte) | G44: Part des réceptions provisoires avec réserves non levées depuis plus de 6 mois. | H44: Réceptions avec réserves non levées > 6 mois ÷ réceptions provisoires × 100 | I44: % | J44: Plus bas = mieux | K44: 0 | L44: 25 | M44: ≤ 0 % | N44: > 0 à 25 % | O44: > 25 % | P44: MO | Q44: MO | R44: Mensuelle | S44: Receptions (à créer) | T44: Affine le suivi de clôture ; non bloquant pour le pilote.
A46: Note : Seuil_Vert / Seuil_Rouge en bleu = valeurs saisies (provisoires, à recalibrer). Importance, Phase et Sens sont modifiables par liste déroulante.

Sheet 02_Regles_Alertes
A1: Regle_ID | B1: Nom | C1: Niveau | D1: Importance | E1: Phase | F1: Condition (lisible) | G1: Logique | H1: C1_KPI_ou_champ | I1: C1_Op | J1: C1_Seuil | K1: C2_KPI_ou_champ | L1: C2_Op | M1: C2_Seuil | N1: C3_KPI_ou_champ | O1: C3_Op | P1: C3_Seuil | Q1: Destinataire | R1: Action | S1: Fréquence | T1: Origine | U1: Changement par rapport à l'ancienne règle
A2: AL01 | B2: Avant-coureur d'abandon | C2: ROUGE | D2: [A] | E2: V2 | F2: Retard de paiement > 60 j ET (cadence récente < 0,70 OU mobilisation < 70 %) | G2: C1 ET (C2 OU C3) | H2: FI6 | I2: > | J2: 60 | K2: AV3 | L2: < | M2: 0.7 | N2: PP2 | O2: < | P2: 70 | Q2: MO + CNED | R2: Revue contractuelle immédiate ; plan de continuité | S2: Hebdomadaire | T2: AL01 (modifiée) | U2: Seuil de paiement 180 j → 60 j (aligné sur FI6) ; condition « ODS refusé » (non modélisée) supprimée ; trois ET remplacés par ET + OU pour qu'elle se déclenche avant l'abandon et non après.
A3: AL02 | B3: Emprise bloquée critique | C3: ROUGE | D3: [M] | E3: MVP | F3: Emprise libérée < 50 % ET délai consommé > 60 % ET aucun plan de déblocage validé | G3: C1 ET C2 ET C3 | H3: QR1 | I3: < | J3: 50 | K3: DL1 | L3: > | M3: 60 | N3: Blocage.Plan_Valide | O3: = | P3: Non | Q3: MO + CNED + responsable territorial | R3: Escalade institutionnelle | S3: Mensuelle | T3: AL02 | U3: Conditions inchangées, désormais reliées à QR1 (qui existe maintenant comme KPI).
A4: AL03 | B4: Étranglement financier | C4: ROUGE | D4: [S] | E4: V2 | F4: Couverture du reste à faire < 90 % ET (réévaluation en attente > 120 j OU couverture des CP < 80 %) | G4: C1 ET (C2 OU C3) | H4: FI2 | I4: < | J4: 90 | K4: FI5 | L4: > | M4: 120 | N4: FI3 | O4: < | P4: 80 | Q4: Contrôleur budgétaire + CNED | R4: Arbitrage financement / réévaluation | S4: Mensuelle | T4: AL03 (modifiée) | U4: « Engagement > 95 % » (qui n'est pas un signal de santé) remplacé par la couverture du reste à faire ; ajout des crédits de paiement.
A5: AL04 | B5: Dégradation contractant | C5: ORANGE | D5: [A] | E5: V2 | F5: Baisse de santé du contractant > 10 pts en un mois ET mobilisation < 70 % ET retard de paiement > 60 j | G5: C1 ET C2 ET C3 | H5: CO1 (variation mensuelle) | I5: < | J5: -10 | K5: PP2 | L5: < | M5: 70 | N5: FI6 | O5: > | P5: 60 | Q5: MO | R5: Plan de redressement du contractant | S5: Hebdomadaire | T5: AL04 (modifiée) | U5: ISC, TMM et paiements remplacés par CO1, PP2 et FI6.
A6: AL05 | B6: Déblocage critique qui approche | C6: ORANGE | D6: [A] | E6: V2 | F6: Date de déblocage estimée dans ≤ 60 j ET blocage en cours ET plan non confirmé | G6: C1 ET C2 ET C3 | H6: Blocage.Jours_avant_date_estimee | I6: <= | J6: 60 | K6: Blocage.Statut | L6: = | M6: Ouvert | N6: Blocage.Plan_Confirme | O6: = | P6: Non | Q6: MO + responsable du déblocage | R6: Confirmer les actions et la date cible | S6: Hebdomadaire | T6: AL05 | U6: Inchangée ; s'appuie sur les champs de la table des blocages (pas sur un KPI).
A7: AL06 | B7: Dérive de délai | C7: ROUGE | D7: [M] | E7: MVP | F7: Délai en vigueur dépassé ET indice d'avancement < 0,70 ET projet non achevé | G7: C1 ET C2 ET C3 | H7: DL1 | I7: > | J7: 100 | K7: AV2 | L7: < | M7: 0.7 | N7: Projet.Statut | O7: ≠ | P7: Achevé | Q7: MO + CNED | R7: Plan de rattrapage | S7: Mensuelle | T7: AL06 (modifiée) | U7: « TAP < 90 % » remplacé par AV2 < 0,70 : l'ancienne règle se serait déclenchée sur une bonne quinzaine de fiches (saturation).
A8: AL07 | B8: Sous-performance physique | C8: ORANGE | D8: [A] | E8: V2 | F8: Indice d'avancement < 0,70 sur ≥ 2 périodes ET cadence récente < 0,70 | G8: C1 ET C2 | H8: AV2 (2 périodes) | I8: < | J8: 0.7 | K8: AV3 | L8: < | M8: 0.7 | Q8: MO + contractant | R8: Plan de rattrapage sous 7 jours | S8: Mensuelle | T8: AL07 (modifiée) | U8: Seuils reliés à AV2 et AV3.
A9: AL08 | B9: Dérive d'AE | C9: ROUGE | D9: [M] | E9: MVP | F9: Dérive d'AE ajustée > 60 % ET réévaluation en attente > 60 j | G9: C1 ET C2 | H9: FI4 | I9: > | J9: 60 | K9: FI5 | L9: > | M9: 60 | Q9: Finance + MO | R9: Analyse des causes et sécurisation de l'AE | S9: Mensuelle | T9: AL08 (modifiée) | U9: Seuil 15 % → 60 % (à 15 %, 20 projets sur 24 se déclenchaient) ; condition « impact délai > 60 j » retirée.
A10: AL09 | B10: NC critique persistante | C10: ROUGE | D10: [A] | E10: V2 | F10: NC critique ouverte > 30 j ET action corrective non validée | G10: C1 ET C2 | H10: QR7 | I10: > | J10: 30 | K10: NC.Action_Validee | L10: = | M10: Non | Q10: BET + MO | R10: Action corrective immédiate | S10: Hebdomadaire | T10: AL09 | U10: Inchangée ; reliée à QR7.
A11: AL10 | B11: Responsable de blocage absent | C11: ORANGE | D11: [M] | E11: MVP | F11: Blocage ouvert > 30 j ET responsable vide | G11: C1 ET C2 | H11: Blocage.Age_jours | I11: > | J11: 30 | K11: Blocage.Responsable | L11: = | M11: Vide | Q11: CNED / PMO | R11: Nommer un responsable et une date cible | S11: Mensuelle | T11: AL10 | U11: Inchangée ; alimente GV1.
A12: AL11 | B12: Paiement anormalement lent | C12: ROUGE | D12: [A] | E12: V2 | F12: Retard de paiement des situations > 60 j OU situation individuelle > 90 j | G12: C1 OU C2 | H12: FI6 | I12: > | J12: 60 | K12: Situation.Age_jours | L12: > | M12: 90 | Q12: Finance + MO | R12: Identifier la cause et fixer une date de paiement | S12: Hebdomadaire | T12: AL11 (modifiée) | U12: Niveau ORANGE → ROUGE pour être cohérent avec le seuil Rouge de FI6 (> 60 j).
A13: AL12 | B13: Maturation critique | C13: ORANGE | D13: [A] | E13: V2 | F13: Modification de consistance en cours ET avancement < 50 % ET avenant en préparation | G13: C1 ET C2 ET C3 | H13: QR6 | I13: = | J13: Oui | K13: AV1 | L13: < | M13: 50 | N13: Avenant.Statut | O13: = | P13: En préparation | Q13: MO + BET | R13: Revue technique du périmètre | S13: Mensuelle | T13: AL12 (modifiée) | U13: Reliée à QR6 et AV1.
A14: AL13 | B14: Dérive de délai extrême | C14: ORANGE | D14: [M] | E14: MVP | F14: Délai en vigueur > 2 × le délai initial ET délai en vigueur dépassé | G14: C1 ET C2 | H14: DL2 | I14: > | J14: 2 | K14: DL1 | L14: > | M14: 100 | Q14: CNED | R14: Revue contractuelle : poursuite, résiliation ou réengagement | S14: Mensuelle | T14: Nouvelle | U14: Couvre la pathologie n°1 du portefeuille (ex. 24 mois devenus 110), sans règle dédiée auparavant.
A15: AL14 | B15: Avenant bloqué au visa | C15: ORANGE | D15: [M] | E15: MVP | F15: Avenant non visé par la CSM depuis plus de 120 j | G15: C1 | H15: GV2 | I15: > | J15: 120 | Q15: MO + CNED | R15: Relancer la CSM ; lever les réserves | S15: Mensuelle | T15: Nouvelle | U15: Goulot très présent dans les fiches (visa avec réserves, ajournements).
A16: AL15 | B16: Arrêt prolongé | C16: ROUGE | D16: [M] | E16: MVP | F16: Temps perdu à l'arrêt > 15 % OU arrêt en cours depuis > 60 j | G16: C1 OU C2 | H16: QR4 | I16: > | J16: 15 | K16: Projet.Arret_en_cours_jours | L16: > | M16: 60 | Q16: CNED + MO | R16: Plan de reprise ; sécuriser les travaux déjà réalisés | S16: Mensuelle | T16: Nouvelle | U16: Les projets à l'arrêt (Skikda, Ténès, Guelma…) n'avaient aucune règle dédiée.
A17: AL16 | B17: Données peu fiables | C17: ORANGE | D17: [M] | E17: MVP | F17: Fraîcheur > 2 OU cohérence : anomalies > 20 % des projets | G17: C1 OU C2 | H17: DO1 | I17: > | J17: 2 | K17: DO3 | L17: > | M17: 20 | Q17: PMO | R17: Corriger / valider les données avant diffusion des KPI | S17: Mensuelle | T17: Nouvelle | U17: Empêche de tirer des conclusions sur des KPI calculés sur des données périmées ou incohérentes.
A18: AL17 | B18: Blocage ancien | C18: ORANGE | D18: [M] | E18: MVP | F18: Âge médian des blocages ouverts > 90 j | G18: C1 | H18: QR3 | I18: > | J18: 90 | Q18: CNED / PMO | R18: Escalade au niveau décisionnel | S18: Mensuelle | T18: Nouvelle | U18: Complète AL10 : AL10 vise l'absence de responsable, AL17 la stagnation.
A20: Notes :
A21: • Les seuils des conditions reprennent les seuils Rouge/Orange de 01_KPI (provisoires, à recalibrer). Un champ de type « Objet.Champ » (ex. Blocage.Plan_Valide) provient d'une table du modèle de données, pas d'un KPI.
A22: • Importance : [M] = règle utilisable dès le pilote avec les KPI obligatoires ; [A] = règle avancée (données de détail, V2) ; [S] = règle stratégique de décision.
A23: • Une règle ne produit une alerte que si ses KPI ont une Confiance suffisante (voir DO1 à DO3) ; une alerte est toujours une proposition de revue, jamais une action automatique (pas de mise en demeure automatisée).
A24: • Fréquence : mensuelle tant que la source reste le suivi semestriel / mensuel du CNED ; hebdomadaire dès qu'une saisie MO / terrain existe.
A25: • Modèle de données recommandé pour le moteur : Regles_Alertes (Regle_ID, Nom, Niveau, Importance, Logique, C1..C3 = KPI/champ + opérateur + seuil, Destinataire, Action, Fréquence, Version, Actif) et Alertes (Alerte_ID, Regle_ID, Projet_ID, Marche_ID, Date, Valeurs_déclenchantes, Confiance, Statut, Responsable, Date_clôture).

Sheet 03_Matrice_Roles
A1: Qui voit quoi — matrice KPI × rôles et alertes × rôles
A2: R = responsable du KPI (valide et rend compte) · S = alimente la donnée sans en être responsable · V = consulte · vide = ne voit pas. Alertes : D = destinataire (doit agir) · I = informé. Codes modifiables (bleu) ; la feuille 04_Vue_Role se met à jour toute seule.
A3: KPI_ID | B3: Nom_KPI | C3: Importance | D3: Phase | E3: =$M$4 -> Direction CNED (décideur) | F3: =$M$5 -> CNED / PMO (analyste) | G3: =$M$6 -> Maître d'ouvrage (MO) | H3: =$M$7 -> Bureau d'études (BET) / contrôle | I3: =$M$8 -> Contractant (entreprise) | J3: =$M$9 -> Contrôleur budgétaire (Finance) | K3: Rang_vue_rôle | L3: Remarque de périmètre | M3: Rôle | N3: Périmètre de données | O3: Ce que le rôle voit
A4: AV1 | B4: =INDEX('01_KPI'!$C$2:$C$44,MATCH($A4,'01_KPI'!$A$2:$A$44,0)) -> Avancement physique consolidé | C4: =INDEX('01_KPI'!$D$2:$D$44,MATCH($A4,'01_KPI'!$A$2:$A$44,0)) -> [M] | D4: =INDEX('01_KPI'!$E$2:$E$44,MATCH($A4,'01_KPI'!$A$2:$A$44,0)) -> MVP | F4: S | G4: R | H4: V | I4: V | J4: V | K4: =IF(INDEX($E4:$J4,'04_Vue_Role'!$B$4)="","",MAX(K$3:K3)+1) | M4: Direction CNED (décideur) | N4: Portefeuille national (tous les projets) | O4: Synthèse de pilotage : KPI [S] et [M] clés, arbitrage des alertes ROUGE.
A5: AV2 | B5: =INDEX('01_KPI'!$C$2:$C$44,MATCH($A5,'01_KPI'!$A$2:$A$44,0)) -> Indice d'avancement | C5: =INDEX('01_KPI'!$D$2:$D$44,MATCH($A5,'01_KPI'!$A$2:$A$44,0)) -> [M] | D5: =INDEX('01_KPI'!$E$2:$E$44,MATCH($A5,'01_KPI'!$A$2:$A$44,0)) -> MVP | E5: V | F5: R | G5: V | H5: V | I5: V | J5: V | K5: =IF(INDEX($E5:$J5,'04_Vue_Role'!$B$4)="","",MAX(K$3:K4)+1) -> 1 | M5: CNED / PMO (analyste) | N5: Portefeuille national (tous les projets) | O5: Tous les KPI utiles à l'analyse ; responsable de la qualité des données (DO1 à DO3) et des KPI de portefeuille.
A6: AV3 | B6: =INDEX('01_KPI'!$C$2:$C$44,MATCH($A6,'01_KPI'!$A$2:$A$44,0)) -> Cadence récente | C6: =INDEX('01_KPI'!$D$2:$D$44,MATCH($A6,'01_KPI'!$A$2:$A$44,0)) -> [A] | D6: =INDEX('01_KPI'!$E$2:$E$44,MATCH($A6,'01_KPI'!$A$2:$A$44,0)) -> V2 | F6: V | G6: R | H6: S | I6: V | K6: =IF(INDEX($E6:$J6,'04_Vue_Role'!$B$4)="","",MAX(K$3:K5)+1) | M6: Maître d'ouvrage (MO) | N6: Ses projets uniquement | O6: KPI de pilotage de ses projets ; alimente avancement, délais, blocages, emprises.
A7: AV4 | B7: =INDEX('01_KPI'!$C$2:$C$44,MATCH($A7,'01_KPI'!$A$2:$A$44,0)) -> Part non contractualisée | C7: =INDEX('01_KPI'!$D$2:$D$44,MATCH($A7,'01_KPI'!$A$2:$A$44,0)) -> [A] | D7: =INDEX('01_KPI'!$E$2:$E$44,MATCH($A7,'01_KPI'!$A$2:$A$44,0)) -> MVP | F7: V | G7: R | K7: =IF(INDEX($E7:$J7,'04_Vue_Role'!$B$4)="","",MAX(K$3:K6)+1) | M7: Bureau d'études (BET) / contrôle | N7: Projets et marchés qu'il surveille | O7: KPI techniques et qualité ; alimente non-conformités, HSE et consistance.
A8: AV5 | B8: =INDEX('01_KPI'!$C$2:$C$44,MATCH($A8,'01_KPI'!$A$2:$A$44,0)) -> Mise en service fonctionnelle | C8: =INDEX('01_KPI'!$D$2:$D$44,MATCH($A8,'01_KPI'!$A$2:$A$44,0)) -> [S] | D8: =INDEX('01_KPI'!$E$2:$E$44,MATCH($A8,'01_KPI'!$A$2:$A$44,0)) -> MVP | E8: V | F8: R | G8: S | K8: =IF(INDEX($E8:$J8,'04_Vue_Role'!$B$4)="","",MAX(K$3:K7)+1) -> 2 | M8: Contractant (entreprise) | N8: Ses propres marchés uniquement | O8: Sa propre performance et ce qui l'affecte (paiements, emprises, avenants) ; jamais les KPI ni les scores d'autres contractants.
A9: FI1 | B9: =INDEX('01_KPI'!$C$2:$C$44,MATCH($A9,'01_KPI'!$A$2:$A$44,0)) -> Écart physique–financier | C9: =INDEX('01_KPI'!$D$2:$D$44,MATCH($A9,'01_KPI'!$A$2:$A$44,0)) -> [M] | D9: =INDEX('01_KPI'!$E$2:$E$44,MATCH($A9,'01_KPI'!$A$2:$A$44,0)) -> MVP | F9: V | G9: R | I9: V | J9: S | K9: =IF(INDEX($E9:$J9,'04_Vue_Role'!$B$4)="","",MAX(K$3:K8)+1) | M9: Contrôleur budgétaire (Finance) | N9: Projets de son périmètre budgétaire | O9: KPI financiers (AE, CP, situations) et alertes financières.
A10: FI2 | B10: =INDEX('01_KPI'!$C$2:$C$44,MATCH($A10,'01_KPI'!$A$2:$A$44,0)) -> Couverture du reste à faire | C10: =INDEX('01_KPI'!$D$2:$D$44,MATCH($A10,'01_KPI'!$A$2:$A$44,0)) -> [S] | D10: =INDEX('01_KPI'!$E$2:$E$44,MATCH($A10,'01_KPI'!$A$2:$A$44,0)) -> V2 | E10: V | F10: V | G10: R | J10: S | K10: =IF(INDEX($E10:$J10,'04_Vue_Role'!$B$4)="","",MAX(K$3:K9)+1) -> 3
A11: FI3 | B11: =INDEX('01_KPI'!$C$2:$C$44,MATCH($A11,'01_KPI'!$A$2:$A$44,0)) -> Couverture des crédits de paiement | C11: =INDEX('01_KPI'!$D$2:$D$44,MATCH($A11,'01_KPI'!$A$2:$A$44,0)) -> [S] | D11: =INDEX('01_KPI'!$E$2:$E$44,MATCH($A11,'01_KPI'!$A$2:$A$44,0)) -> V2 | E11: V | F11: V | G11: V | J11: R | K11: =IF(INDEX($E11:$J11,'04_Vue_Role'!$B$4)="","",MAX(K$3:K10)+1) -> 4
A12: FI4 | B12: =INDEX('01_KPI'!$C$2:$C$44,MATCH($A12,'01_KPI'!$A$2:$A$44,0)) -> Dérive d'AE ajustée | C12: =INDEX('01_KPI'!$D$2:$D$44,MATCH($A12,'01_KPI'!$A$2:$A$44,0)) -> [M] | D12: =INDEX('01_KPI'!$E$2:$E$44,MATCH($A12,'01_KPI'!$A$2:$A$44,0)) -> MVP | E12: V | F12: V | G12: V | J12: R | K12: =IF(INDEX($E12:$J12,'04_Vue_Role'!$B$4)="","",MAX(K$3:K11)+1) -> 5
A13: FI5 | B13: =INDEX('01_KPI'!$C$2:$C$44,MATCH($A13,'01_KPI'!$A$2:$A$44,0)) -> Réévaluations d'AE en attente | C13: =INDEX('01_KPI'!$D$2:$D$44,MATCH($A13,'01_KPI'!$A$2:$A$44,0)) -> [M] | D13: =INDEX('01_KPI'!$E$2:$E$44,MATCH($A13,'01_KPI'!$A$2:$A$44,0)) -> MVP | E13: V | F13: S | G13: V | J13: R | K13: =IF(INDEX($E13:$J13,'04_Vue_Role'!$B$4)="","",MAX(K$3:K12)+1) -> 6
A14: FI6 | B14: =INDEX('01_KPI'!$C$2:$C$44,MATCH($A14,'01_KPI'!$A$2:$A$44,0)) -> Retard de paiement des situations | C14: =INDEX('01_KPI'!$D$2:$D$44,MATCH($A14,'01_KPI'!$A$2:$A$44,0)) -> [A] | D14: =INDEX('01_KPI'!$E$2:$E$44,MATCH($A14,'01_KPI'!$A$2:$A$44,0)) -> V2 | F14: V | G14: R | I14: V | J14: S | K14: =IF(INDEX($E14:$J14,'04_Vue_Role'!$B$4)="","",MAX(K$3:K13)+1) | L14: Contractant : ses propres situations.
A15: FI7 | B15: =INDEX('01_KPI'!$C$2:$C$44,MATCH($A15,'01_KPI'!$A$2:$A$44,0)) -> Encours de situations | C15: =INDEX('01_KPI'!$D$2:$D$44,MATCH($A15,'01_KPI'!$A$2:$A$44,0)) -> [A] | D15: =INDEX('01_KPI'!$E$2:$E$44,MATCH($A15,'01_KPI'!$A$2:$A$44,0)) -> V2 | F15: V | G15: V | I15: V | J15: R | K15: =IF(INDEX($E15:$J15,'04_Vue_Role'!$B$4)="","",MAX(K$3:K14)+1) | L15: Contractant : ses propres situations.
A16: DL1 | B16: =INDEX('01_KPI'!$C$2:$C$44,MATCH($A16,'01_KPI'!$A$2:$A$44,0)) -> Consommation du délai en vigueur | C16: =INDEX('01_KPI'!$D$2:$D$44,MATCH($A16,'01_KPI'!$A$2:$A$44,0)) -> [M] | D16: =INDEX('01_KPI'!$E$2:$E$44,MATCH($A16,'01_KPI'!$A$2:$A$44,0)) -> MVP | F16: V | G16: R | H16: V | I16: V | J16: V | K16: =IF(INDEX($E16:$J16,'04_Vue_Role'!$B$4)="","",MAX(K$3:K15)+1)
A17: DL2 | B17: =INDEX('01_KPI'!$C$2:$C$44,MATCH($A17,'01_KPI'!$A$2:$A$44,0)) -> Dérive de délai par avenants | C17: =INDEX('01_KPI'!$D$2:$D$44,MATCH($A17,'01_KPI'!$A$2:$A$44,0)) -> [M] | D17: =INDEX('01_KPI'!$E$2:$E$44,MATCH($A17,'01_KPI'!$A$2:$A$44,0)) -> MVP | E17: V | F17: R | G17: V | H17: V | I17: V | J17: V | K17: =IF(INDEX($E17:$J17,'04_Vue_Role'!$B$4)="","",MAX(K$3:K16)+1) -> 7
A18: DL3 | B18: =INDEX('01_KPI'!$C$2:$C$44,MATCH($A18,'01_KPI'!$A$2:$A$44,0)) -> Dépassement de la date contractuelle | C18: =INDEX('01_KPI'!$D$2:$D$44,MATCH($A18,'01_KPI'!$A$2:$A$44,0)) -> [M] | D18: =INDEX('01_KPI'!$E$2:$E$44,MATCH($A18,'01_KPI'!$A$2:$A$44,0)) -> MVP | E18: V | F18: R | G18: V | H18: V | I18: V | J18: V | K18: =IF(INDEX($E18:$J18,'04_Vue_Role'!$B$4)="","",MAX(K$3:K17)+1) -> 8
A19: DL4 | B19: =INDEX('01_KPI'!$C$2:$C$44,MATCH($A19,'01_KPI'!$A$2:$A$44,0)) -> Date d'achèvement prévisionnelle | C19: =INDEX('01_KPI'!$D$2:$D$44,MATCH($A19,'01_KPI'!$A$2:$A$44,0)) -> [S] | D19: =INDEX('01_KPI'!$E$2:$E$44,MATCH($A19,'01_KPI'!$A$2:$A$44,0)) -> V2 | E19: V | F19: V | G19: R | H19: S | I19: V | K19: =IF(INDEX($E19:$J19,'04_Vue_Role'!$B$4)="","",MAX(K$3:K18)+1) -> 9
A20: BU1 | B20: =INDEX('01_KPI'!$C$2:$C$44,MATCH($A20,'01_KPI'!$A$2:$A$44,0)) -> Poids financier des avenants | C20: =INDEX('01_KPI'!$D$2:$D$44,MATCH($A20,'01_KPI'!$A$2:$A$44,0)) -> [M] | D20: =INDEX('01_KPI'!$E$2:$E$44,MATCH($A20,'01_KPI'!$A$2:$A$44,0)) -> MVP | E20: V | F20: R | G20: S | I20: V | J20: V | K20: =IF(INDEX($E20:$J20,'04_Vue_Role'!$B$4)="","",MAX(K$3:K19)+1) -> 10
A21: BU2 | B21: =INDEX('01_KPI'!$C$2:$C$44,MATCH($A21,'01_KPI'!$A$2:$A$44,0)) -> Nombre d'avenants cumulés | C21: =INDEX('01_KPI'!$D$2:$D$44,MATCH($A21,'01_KPI'!$A$2:$A$44,0)) -> [A] | D21: =INDEX('01_KPI'!$E$2:$E$44,MATCH($A21,'01_KPI'!$A$2:$A$44,0)) -> MVP | F21: V | G21: R | H21: V | I21: V | K21: =IF(INDEX($E21:$J21,'04_Vue_Role'!$B$4)="","",MAX(K$3:K20)+1)
A22: BU3 | B22: =INDEX('01_KPI'!$C$2:$C$44,MATCH($A22,'01_KPI'!$A$2:$A$44,0)) -> Coût final prévisionnel | C22: =INDEX('01_KPI'!$D$2:$D$44,MATCH($A22,'01_KPI'!$A$2:$A$44,0)) -> [S] | D22: =INDEX('01_KPI'!$E$2:$E$44,MATCH($A22,'01_KPI'!$A$2:$A$44,0)) -> V2 | E22: V | F22: V | G22: R | H22: S | J22: V | K22: =IF(INDEX($E22:$J22,'04_Vue_Role'!$B$4)="","",MAX(K$3:K21)+1) -> 11
A23: QR1 | B23: =INDEX('01_KPI'!$C$2:$C$44,MATCH($A23,'01_KPI'!$A$2:$A$44,0)) -> Taux de libération des emprises | C23: =INDEX('01_KPI'!$D$2:$D$44,MATCH($A23,'01_KPI'!$A$2:$A$44,0)) -> [M] | D23: =INDEX('01_KPI'!$E$2:$E$44,MATCH($A23,'01_KPI'!$A$2:$A$44,0)) -> MVP | E23: V | F23: V | G23: R | H23: V | I23: V | K23: =IF(INDEX($E23:$J23,'04_Vue_Role'!$B$4)="","",MAX(K$3:K22)+1) -> 12
A24: QR2 | B24: =INDEX('01_KPI'!$C$2:$C$44,MATCH($A24,'01_KPI'!$A$2:$A$44,0)) -> Interférences réseaux traitées | C24: =INDEX('01_KPI'!$D$2:$D$44,MATCH($A24,'01_KPI'!$A$2:$A$44,0)) -> [M] | D24: =INDEX('01_KPI'!$E$2:$E$44,MATCH($A24,'01_KPI'!$A$2:$A$44,0)) -> MVP | F24: V | G24: R | H24: V | I24: V | K24: =IF(INDEX($E24:$J24,'04_Vue_Role'!$B$4)="","",MAX(K$3:K23)+1)
A25: QR3 | B25: =INDEX('01_KPI'!$C$2:$C$44,MATCH($A25,'01_KPI'!$A$2:$A$44,0)) -> Âge des blocages ouverts | C25: =INDEX('01_KPI'!$D$2:$D$44,MATCH($A25,'01_KPI'!$A$2:$A$44,0)) -> [M] | D25: =INDEX('01_KPI'!$E$2:$E$44,MATCH($A25,'01_KPI'!$A$2:$A$44,0)) -> MVP | E25: V | F25: R | G25: V | H25: V | I25: V | K25: =IF(INDEX($E25:$J25,'04_Vue_Role'!$B$4)="","",MAX(K$3:K24)+1) -> 13
A26: QR4 | B26: =INDEX('01_KPI'!$C$2:$C$44,MATCH($A26,'01_KPI'!$A$2:$A$44,0)) -> Temps perdu à l'arrêt | C26: =INDEX('01_KPI'!$D$2:$D$44,MATCH($A26,'01_KPI'!$A$2:$A$44,0)) -> [M] | D26: =INDEX('01_KPI'!$E$2:$E$44,MATCH($A26,'01_KPI'!$A$2:$A$44,0)) -> MVP | E26: V | F26: V | G26: R | H26: V | I26: V | K26: =IF(INDEX($E26:$J26,'04_Vue_Role'!$B$4)="","",MAX(K$3:K25)+1) -> 14
A27: QR5 | B27: =INDEX('01_KPI'!$C$2:$C$44,MATCH($A27,'01_KPI'!$A$2:$A$44,0)) -> Aléas non prévus ouverts | C27: =INDEX('01_KPI'!$D$2:$D$44,MATCH($A27,'01_KPI'!$A$2:$A$44,0)) -> [A] | D27: =INDEX('01_KPI'!$E$2:$E$44,MATCH($A27,'01_KPI'!$A$2:$A$44,0)) -> V2 | F27: V | G27: R | H27: S | I27: V | K27: =IF(INDEX($E27:$J27,'04_Vue_Role'!$B$4)="","",MAX(K$3:K26)+1)
A28: QR6 | B28: =INDEX('01_KPI'!$C$2:$C$44,MATCH($A28,'01_KPI'!$A$2:$A$44,0)) -> Modification de consistance en cours | C28: =INDEX('01_KPI'!$D$2:$D$44,MATCH($A28,'01_KPI'!$A$2:$A$44,0)) -> [A] | D28: =INDEX('01_KPI'!$E$2:$E$44,MATCH($A28,'01_KPI'!$A$2:$A$44,0)) -> V2 | F28: V | G28: S | H28: R | K28: =IF(INDEX($E28:$J28,'04_Vue_Role'!$B$4)="","",MAX(K$3:K27)+1)
A29: QR7 | B29: =INDEX('01_KPI'!$C$2:$C$44,MATCH($A29,'01_KPI'!$A$2:$A$44,0)) -> Non-conformité critique la plus ancienne | C29: =INDEX('01_KPI'!$D$2:$D$44,MATCH($A29,'01_KPI'!$A$2:$A$44,0)) -> [A] | D29: =INDEX('01_KPI'!$E$2:$E$44,MATCH($A29,'01_KPI'!$A$2:$A$44,0)) -> V2 | F29: V | G29: V | H29: R | I29: V | K29: =IF(INDEX($E29:$J29,'04_Vue_Role'!$B$4)="","",MAX(K$3:K28)+1) | L29: Contractant : les NC qui le concernent.
A30: QR8 | B30: =INDEX('01_KPI'!$C$2:$C$44,MATCH($A30,'01_KPI'!$A$2:$A$44,0)) -> Incidents HSE graves | C30: =INDEX('01_KPI'!$D$2:$D$44,MATCH($A30,'01_KPI'!$A$2:$A$44,0)) -> [A] | D30: =INDEX('01_KPI'!$E$2:$E$44,MATCH($A30,'01_KPI'!$A$2:$A$44,0)) -> Vision | F30: V | G30: V | H30: R | I30: V | K30: =IF(INDEX($E30:$J30,'04_Vue_Role'!$B$4)="","",MAX(K$3:K29)+1) | L30: Contractant : incidents de ses chantiers.
A31: DO1 | B31: =INDEX('01_KPI'!$C$2:$C$44,MATCH($A31,'01_KPI'!$A$2:$A$44,0)) -> Fraîcheur des données | C31: =INDEX('01_KPI'!$D$2:$D$44,MATCH($A31,'01_KPI'!$A$2:$A$44,0)) -> [M] | D31: =INDEX('01_KPI'!$E$2:$E$44,MATCH($A31,'01_KPI'!$A$2:$A$44,0)) -> MVP | F31: R | G31: V | H31: V | K31: =IF(INDEX($E31:$J31,'04_Vue_Role'!$B$4)="","",MAX(K$3:K30)+1)
A32: DO2 | B32: =INDEX('01_KPI'!$C$2:$C$44,MATCH($A32,'01_KPI'!$A$2:$A$44,0)) -> Complétude | C32: =INDEX('01_KPI'!$D$2:$D$44,MATCH($A32,'01_KPI'!$A$2:$A$44,0)) -> [M] | D32: =INDEX('01_KPI'!$E$2:$E$44,MATCH($A32,'01_KPI'!$A$2:$A$44,0)) -> MVP | F32: R | G32: V | H32: V | K32: =IF(INDEX($E32:$J32,'04_Vue_Role'!$B$4)="","",MAX(K$3:K31)+1)
A33: DO3 | B33: =INDEX('01_KPI'!$C$2:$C$44,MATCH($A33,'01_KPI'!$A$2:$A$44,0)) -> Cohérence | C33: =INDEX('01_KPI'!$D$2:$D$44,MATCH($A33,'01_KPI'!$A$2:$A$44,0)) -> [M] | D33: =INDEX('01_KPI'!$E$2:$E$44,MATCH($A33,'01_KPI'!$A$2:$A$44,0)) -> MVP | F33: R | G33: V | H33: V | K33: =IF(INDEX($E33:$J33,'04_Vue_Role'!$B$4)="","",MAX(K$3:K32)+1)
A34: PP1 | B34: =INDEX('01_KPI'!$C$2:$C$44,MATCH($A34,'01_KPI'!$A$2:$A$44,0)) -> Fiabilité du planning hebdomadaire | C34: =INDEX('01_KPI'!$D$2:$D$44,MATCH($A34,'01_KPI'!$A$2:$A$44,0)) -> [A] | D34: =INDEX('01_KPI'!$E$2:$E$44,MATCH($A34,'01_KPI'!$A$2:$A$44,0)) -> V2 | F34: V | G34: R | H34: V | I34: S | K34: =IF(INDEX($E34:$J34,'04_Vue_Role'!$B$4)="","",MAX(K$3:K33)+1)
A35: PP2 | B35: =INDEX('01_KPI'!$C$2:$C$44,MATCH($A35,'01_KPI'!$A$2:$A$44,0)) -> Mobilisation effective | C35: =INDEX('01_KPI'!$D$2:$D$44,MATCH($A35,'01_KPI'!$A$2:$A$44,0)) -> [A] | D35: =INDEX('01_KPI'!$E$2:$E$44,MATCH($A35,'01_KPI'!$A$2:$A$44,0)) -> V2 | F35: V | G35: R | H35: V | I35: S | K35: =IF(INDEX($E35:$J35,'04_Vue_Role'!$B$4)="","",MAX(K$3:K34)+1)
A36: PP3 | B36: =INDEX('01_KPI'!$C$2:$C$44,MATCH($A36,'01_KPI'!$A$2:$A$44,0)) -> Causes de non-réalisation externes | C36: =INDEX('01_KPI'!$D$2:$D$44,MATCH($A36,'01_KPI'!$A$2:$A$44,0)) -> [A] | D36: =INDEX('01_KPI'!$E$2:$E$44,MATCH($A36,'01_KPI'!$A$2:$A$44,0)) -> V2 | F36: V | G36: R | H36: V | I36: S | K36: =IF(INDEX($E36:$J36,'04_Vue_Role'!$B$4)="","",MAX(K$3:K35)+1)
A37: CO1 | B37: =INDEX('01_KPI'!$C$2:$C$44,MATCH($A37,'01_KPI'!$A$2:$A$44,0)) -> Santé du contractant (0–100) | C37: =INDEX('01_KPI'!$D$2:$D$44,MATCH($A37,'01_KPI'!$A$2:$A$44,0)) -> [S] | D37: =INDEX('01_KPI'!$E$2:$E$44,MATCH($A37,'01_KPI'!$A$2:$A$44,0)) -> MVP | E37: V | F37: R | G37: V | I37: V | K37: =IF(INDEX($E37:$J37,'04_Vue_Role'!$B$4)="","",MAX(K$3:K36)+1) -> 15 | L37: Contractant : son propre score uniquement.
A38: CO2 | B38: =INDEX('01_KPI'!$C$2:$C$44,MATCH($A38,'01_KPI'!$A$2:$A$44,0)) -> Concentration par contractant | C38: =INDEX('01_KPI'!$D$2:$D$44,MATCH($A38,'01_KPI'!$A$2:$A$44,0)) -> [S] | D38: =INDEX('01_KPI'!$E$2:$E$44,MATCH($A38,'01_KPI'!$A$2:$A$44,0)) -> V2 | E38: V | F38: R | K38: =IF(INDEX($E38:$J38,'04_Vue_Role'!$B$4)="","",MAX(K$3:K37)+1) -> 16
A39: CO3 | B39: =INDEX('01_KPI'!$C$2:$C$44,MATCH($A39,'01_KPI'!$A$2:$A$44,0)) -> Part en parachèvement après résiliation | C39: =INDEX('01_KPI'!$D$2:$D$44,MATCH($A39,'01_KPI'!$A$2:$A$44,0)) -> [S] | D39: =INDEX('01_KPI'!$E$2:$E$44,MATCH($A39,'01_KPI'!$A$2:$A$44,0)) -> MVP | E39: V | F39: R | K39: =IF(INDEX($E39:$J39,'04_Vue_Role'!$B$4)="","",MAX(K$3:K38)+1) -> 17
A40: CO4 | B40: =INDEX('01_KPI'!$C$2:$C$44,MATCH($A40,'01_KPI'!$A$2:$A$44,0)) -> Projets en retard important | C40: =INDEX('01_KPI'!$D$2:$D$44,MATCH($A40,'01_KPI'!$A$2:$A$44,0)) -> [M] | D40: =INDEX('01_KPI'!$E$2:$E$44,MATCH($A40,'01_KPI'!$A$2:$A$44,0)) -> MVP | E40: V | F40: R | G40: V | J40: V | K40: =IF(INDEX($E40:$J40,'04_Vue_Role'!$B$4)="","",MAX(K$3:K39)+1) -> 18
...

Sheet 04_Vue_Role
A1: Ma vue — KPI et alertes affichés selon le rôle
A3: Rôle | B3: Direction CNED (décideur) | F3: ◄ choisir un rôle dans la liste
A4: Index | B4: =MATCH($B$3,'03_Matrice_Roles'!$M$4:$M$9,0) -> 1
A5: Périmètre | B5: =INDEX('03_Matrice_Roles'!$N$4:$N$9,$B$4) -> Portefeuille national (tous les projets)
A6: Vue | B6: =INDEX('03_Matrice_Roles'!$O$4:$O$9,$B$4) -> Synthèse de pilotage : KPI [S] et [M] clés, arbitrage des alertes ROUGE.
A7: ="KPI visibles : "&MAX('03_Matrice_Roles'!$K$4:$K$46)&" ([M] "&SUMPRODUCT(('03_Matrice_Roles'!$K$4:$K$46<>"")*('03_Matrice_Roles'!$C$4:$C$46="[M]"))&" · [A] "&SUMPRODUCT(('03_Matrice_Roles'!$K$4:$K$46<>"")*('03_Matrice_Roles'!$C$4:$C$46="[A]"))&" · [S] "&SUMPRODUCT(('03_Matrice_Roles'!$K$4:$K$46<>"")*('03_Matrice_Roles'!$C$4:$C$46="[S]"))&") — Règles d'alerte concernées : "&MAX('03_Matrice_Roles'!$K$51:$K$67) -> KPI visibles : 22 ([M] 12 · [A] 1 · [S] 9) — Règles d'alerte concernées : 8
A8: Mes KPI
A9: N° | B9: KPI_ID | C9: Nom_KPI | D9: Importance | E9: Phase | F9: Mon droit | G9: Définition | H9: Unité | I9: Sens | J9: Vert | K9: Orange | L9: Rouge | M9: Fréquence
A10: =IF($B10="","",ROW()-9) -> 1 | B10: =IFERROR(INDEX('03_Matrice_Roles'!$A$4:$A$46,MATCH(ROW()-9,'03_Matrice_Roles'!$K$4:$K$46,0)),"") -> AV2 | C10: =IF($B10="","",INDEX('01_KPI'!$C$2:$C$44,MATCH($B10,'01_KPI'!$A$2:$A$44,0))) -> Indice d'avancement | D10: =IF($B10="","",INDEX('01_KPI'!$D$2:$D$44,MATCH($B10,'01_KPI'!$A$2:$A$44,0))) -> [M] | E10: =IF($B10="","",INDEX('01_KPI'!$E$2:$E$44,MATCH($B10,'01_KPI'!$A$2:$A$44,0))) -> MVP | F10: =IF($B10="","",IF(INDEX('03_Matrice_Roles'!$E$4:$J$46,MATCH($B10,'03_Matrice_Roles'!$A$4:$A$46,0),$B$4)="R","Responsable",IF(INDEX('03_Matrice_Roles'!$E$4:$J$46,MATCH($B10,'03_Matrice_Roles'!$A$4:$A$46,0),$B$4)="S","Alimente","Consulte"))) -> Consulte | G10: =IF($B10="","",INDEX('01_KPI'!$G$2:$G$44,MATCH($B10,'01_KPI'!$A$2:$A$44,0))) -> Compare l'avancement physique au temps déjà consommé ; 1 = projet dans le rythme. | H10: =IF($B10="","",INDEX('01_KPI'!$I$2:$I$44,MATCH($B10,'01_KPI'!$A$2:$A$44,0))) -> ratio | I10: =IF($B10="","",INDEX('01_KPI'!$J$2:$J$44,MATCH($B10,'01_KPI'!$A$2:$A$44,0))) -> Plus haut = mieux | J10: =IF($B10="","",INDEX('01_KPI'!$M$2:$M$44,MATCH($B10,'01_KPI'!$A$2:$A$44,0))) -> ≥ 0.9 ratio | K10: =IF($B10="","",INDEX('01_KPI'!$N$2:$N$44,MATCH($B10,'01_KPI'!$A$2:$A$44,0))) -> de 0.7 à < 0.9 ratio | L10: =IF($B10="","",INDEX('01_KPI'!$O$2:$O$44,MATCH($B10,'01_KPI'!$A$2:$A$44,0))) -> < 0.7 ratio | M10: =IF($B10="","",INDEX('01_KPI'!$R$2:$R$44,MATCH($B10,'01_KPI'!$A$2:$A$44,0))) -> Mensuelle
A11: =IF($B11="","",ROW()-9) -> 2 | B11: =IFERROR(INDEX('03_Matrice_Roles'!$A$4:$A$46,MATCH(ROW()-9,'03_Matrice_Roles'!$K$4:$K$46,0)),"") -> AV5 | C11: =IF($B11="","",INDEX('01_KPI'!$C$2:$C$44,MATCH($B11,'01_KPI'!$A$2:$A$44,0))) -> Mise en service fonctionnelle | D11: =IF($B11="","",INDEX('01_KPI'!$D$2:$D$44,MATCH($B11,'01_KPI'!$A$2:$A$44,0))) -> [S] | E11: =IF($B11="","",INDEX('01_KPI'!$E$2:$E$44,MATCH($B11,'01_KPI'!$A$2:$A$44,0))) -> MVP | F11: =IF($B11="","",IF(INDEX('03_Matrice_Roles'!$E$4:$J$46,MATCH($B11,'03_Matrice_Roles'!$A$4:$A$46,0),$B$4)="R","Responsable",IF(INDEX('03_Matrice_Roles'!$E$4:$J$46,MATCH($B11,'03_Matrice_Roles'!$A$4:$A$46,0),$B$4)="S","Alimente","Consulte"))) -> Consulte | G11: =IF($B11="","",INDEX('01_KPI'!$G$2:$G$44,MATCH($B11,'01_KPI'!$A$2:$A$44,0))) -> Part des ouvrages mis en service qui fonctionnent pleinement (sans réserve ni lot système, signalisation ou énergie en retard). | H11: =IF($B11="","",INDEX('01_KPI'!$I$2:$I$44,MATCH($B11,'01_KPI'!$A$2:$A$44,0))) -> % | I11: =IF($B11="","",INDEX('01_KPI'!$J$2:$J$44,MATCH($B11,'01_KPI'!$A$2:$A$44,0))) -> Plus haut = mieux | J11: =IF($B11="","",INDEX('01_KPI'!$M$2:$M$44,MATCH($B11,'01_KPI'!$A$2:$A$44,0))) -> ≥ 90 % | K11: =IF($B11="","",INDEX('01_KPI'!$N$2:$N$44,MATCH($B11,'01_KPI'!$A$2:$A$44,0))) -> de 60 à < 90 % | L11: =IF($B11="","",INDEX('01_KPI'!$O$2:$O$44,MATCH($B11,'01_KPI'!$A$2:$A$44,0))) -> < 60 % | M11: =IF($B11="","",INDEX('01_KPI'!$R$2:$R$44,MATCH($B11,'01_KPI'!$A$2:$A$44,0))) -> Mensuelle
A12: =IF($B12="","",ROW()-9) -> 3 | B12: =IFERROR(INDEX('03_Matrice_Roles'!$A$4:$A$46,MATCH(ROW()-9,'03_Matrice_Roles'!$K$4:$K$46,0)),"") -> FI2 | C12: =IF($B12="","",INDEX('01_KPI'!$C$2:$C$44,MATCH($B12,'01_KPI'!$A$2:$A$44,0))) -> Couverture du reste à faire | D12: =IF($B12="","",INDEX('01_KPI'!$D$2:$D$44,MATCH($B12,'01_KPI'!$A$2:$A$44,0))) -> [S] | E12: =IF($B12="","",INDEX('01_KPI'!$E$2:$E$44,MATCH($B12,'01_KPI'!$A$2:$A$44,0))) -> V2 | F12: =IF($B12="","",IF(INDEX('03_Matrice_Roles'!$E$4:$J$46,MATCH($B12,'03_Matrice_Roles'!$A$4:$A$46,0),$B$4)="R","Responsable",IF(INDEX('03_Matrice_Roles'!$E$4:$J$46,MATCH($B12,'03_Matrice_Roles'!$A$4:$A$46,0),$B$4)="S","Alimente","Consulte"))) -> Consulte | G12: =IF($B12="","",INDEX('01_KPI'!$G$2:$G$44,MATCH($B12,'01_KPI'!$A$2:$A$44,0))) -> Capacité des ressources financières restantes à couvrir ce qu'il reste à payer, avenants en préparation compris. | H12: =IF($B12="","",INDEX('01_KPI'!$I$2:$I$44,MATCH($B12,'01_KPI'!$A$2:$A$44,0))) -> % | I12: =IF($B12="","",INDEX('01_KPI'!$J$2:$J$44,MATCH($B12,'01_KPI'!$A$2:$A$44,0))) -> Plus haut = mieux | J12: =IF($B12="","",INDEX('01_KPI'!$M$2:$M$44,MATCH($B12,'01_KPI'!$A$2:$A$44,0))) -> ≥ 100 % | K12: =IF($B12="","",INDEX('01_KPI'!$N$2:$N$44,MATCH($B12,'01_KPI'!$A$2:$A$44,0))) -> de 90 à < 100 % | L12: =IF($B12="","",INDEX('01_KPI'!$O$2:$O$44,MATCH($B12,'01_KPI'!$A$2:$A$44,0))) -> < 90 % | M12: =IF($B12="","",INDEX('01_KPI'!$R$2:$R$44,MATCH($B12,'01_KPI'!$A$2:$A$44,0))) -> Mensuelle
A13: =IF($B13="","",ROW()-9) -> 4 | B13: =IFERROR(INDEX('03_Matrice_Roles'!$A$4:$A$46,MATCH(ROW()-9,'03_Matrice_Roles'!$K$4:$K$46,0)),"") -> FI3 | C13: =IF($B13="","",INDEX('01_KPI'!$C$2:$C$44,MATCH($B13,'01_KPI'!$A$2:$A$44,0))) -> Couverture des crédits de paiement | D13: =IF($B13="","",INDEX('01_KPI'!$D$2:$D$44,MATCH($B13,'01_KPI'!$A$2:$A$44,0))) -> [S] | E13: =IF($B13="","",INDEX('01_KPI'!$E$2:$E$44,MATCH($B13,'01_KPI'!$A$2:$A$44,0))) -> V2 | F13: =IF($B13="","",IF(INDEX('03_Matrice_Roles'!$E$4:$J$46,MATCH($B13,'03_Matrice_Roles'!$A$4:$A$46,0),$B$4)="R","Responsable",IF(INDEX('03_Matrice_Roles'!$E$4:$J$46,MATCH($B13,'03_Matrice_Roles'!$A$4:$A$46,0),$B$4)="S","Alimente","Consulte"))) -> Consulte | G13: =IF($B13="","",INDEX('01_KPI'!$G$2:$G$44,MATCH($B13,'01_KPI'!$A$2:$A$44,0))) -> Les crédits de paiement de l'exercice couvrent-ils les paiements prévus ? (insuffisance des CP : contrainte récurrente.) | H13: =IF($B13="","",INDEX('01_KPI'!$I$2:$I$44,MATCH($B13,'01_KPI'!$A$2:$A$44,0))) -> % | I13: =IF($B13="","",INDEX('01_KPI'!$J$2:$J$44,MATCH($B13,'01_KPI'!$A$2:$A$44,0))) -> Plus haut = mieux | J13: =IF($B13="","",INDEX('01_KPI'!$M$2:$M$44,MATCH($B13,'01_KPI'!$A$2:$A$44,0))) -> ≥ 100 % | K13: =IF($B13="","",INDEX('01_KPI'!$N$2:$N$44,MATCH($B13,'01_KPI'!$A$2:$A$44,0))) -> de 80 à < 100 % | L13: =IF($B13="","",INDEX('01_KPI'!$O$2:$O$44,MATCH($B13,'01_KPI'!$A$2:$A$44,0))) -> < 80 % | M13: =IF($B13="","",INDEX('01_KPI'!$R$2:$R$44,MATCH($B13,'01_KPI'!$A$2:$A$44,0))) -> Mensuelle
A14: =IF($B14="","",ROW()-9) -> 5 | B14: =IFERROR(INDEX('03_Matrice_Roles'!$A$4:$A$46,MATCH(ROW()-9,'03_Matrice_Roles'!$K$4:$K$46,0)),"") -> FI4 | C14: =IF($B14="","",INDEX('01_KPI'!$C$2:$C$44,MATCH($B14,'01_KPI'!$A$2:$A$44,0))) -> Dérive d'AE ajustée | D14: =IF($B14="","",INDEX('01_KPI'!$D$2:$D$44,MATCH($B14,'01_KPI'!$A$2:$A$44,0))) -> [M] | E14: =IF($B14="","",INDEX('01_KPI'!$E$2:$E$44,MATCH($B14,'01_KPI'!$A$2:$A$44,0))) -> MVP | F14: =IF($B14="","",IF(INDEX('03_Matrice_Roles'!$E$4:$J$46,MATCH($B14,'03_Matrice_Roles'!$A$4:$A$46,0),$B$4)="R","Responsable",IF(INDEX('03_Matrice_Roles'!$E$4:$J$46,MATCH($B14,'03_Matrice_Roles'!$A$4:$A$46,0),$B$4)="S","Alimente","Consulte"))) -> Consulte | G14: =IF($B14="","",INDEX('01_KPI'!$G$2:$G$44,MATCH($B14,'01_KPI'!$A$2:$A$44,0))) -> Augmentation de l'AE par rapport à l'AE initiale, après neutralisation des transferts de maîtrise d'ouvrage ou de périmètre. | H14: =IF($B14="","",INDEX('01_KPI'!$I$2:$I$44,MATCH($B14,'01_KPI'!$A$2:$A$44,0))) -> % | I14: =IF($B14="","",INDEX('01_KPI'!$J$2:$J$44,MATCH($B14,'01_KPI'!$A$2:$A$44,0))) -> Plus bas = mieux | J14: =IF($B14="","",INDEX('01_KPI'!$M$2:$M$44,MATCH($B14,'01_KPI'!$A$2:$A$44,0))) -> ≤ 20 % | K14: =IF($B14="","",INDEX('01_KPI'!$N$2:$N$44,MATCH($B14,'01_KPI'!$A$2:$A$44,0))) -> > 20 à 60 % | L14: =IF($B14="","",INDEX('01_KPI'!$O$2:$O$44,MATCH($B14,'01_KPI'!$A$2:$A$44,0))) -> > 60 % | M14: =IF($B14="","",INDEX('01_KPI'!$R$2:$R$44,MATCH($B14,'01_KPI'!$A$2:$A$44,0))) -> Mensuelle
A15: =IF($B15="","",ROW()-9) -> 6 | B15: =IFERROR(INDEX('03_Matrice_Roles'!$A$4:$A$46,MATCH(ROW()-9,'03_Matrice_Roles'!$K$4:$K$46,0)),"") -> FI5 | C15: =IF($B15="","",INDEX('01_KPI'!$C$2:$C$44,MATCH($B15,'01_KPI'!$A$2:$A$44,0))) -> Réévaluations d'AE en attente | D15: =IF($B15="","",INDEX('01_KPI'!$D$2:$D$44,MATCH($B15,'01_KPI'!$A$2:$A$44,0))) -> [M] | E15: =IF($B15="","",INDEX('01_KPI'!$E$2:$E$44,MATCH($B15,'01_KPI'!$A$2:$A$44,0))) -> MVP | F15: =IF($B15="","",IF(INDEX('03_Matrice_Roles'!$E$4:$J$46,MATCH($B15,'03_Matrice_Roles'!$A$4:$A$46,0),$B$4)="R","Responsable",IF(INDEX('03_Matrice_Roles'!$E$4:$J$46,MATCH($B15,'03_Matrice_Roles'!$A$4:$A$46,0),$B$4)="S","Alimente","Consulte"))) -> Consulte | G15: =IF($B15="","",INDEX('01_KPI'!$G$2:$G$44,MATCH($B15,'01_KPI'!$A$2:$A$44,0))) -> Ancienneté de la plus ancienne réévaluation d'AE non encore approuvée ; le montant en attente est affiché à côté. | H15: =IF($B15="","",INDEX('01_KPI'!$I$2:$I$44,MATCH($B15,'01_KPI'!$A$2:$A$44,0))) -> j | I15: =IF($B15="","",INDEX('01_KPI'!$J$2:$J$44,MATCH($B15,'01_KPI'!$A$2:$A$44,0))) -> Plus bas = mieux | J15: =IF($B15="","",INDEX('01_KPI'!$M$2:$M$44,MATCH($B15,'01_KPI'!$A$2:$A$44,0))) -> ≤ 60 j | K15: =IF($B15="","",INDEX('01_KPI'!$N$2:$N$44,MATCH($B15,'01_KPI'!$A$2:$A$44,0))) -> > 60 à 120 j | L15: =IF($B15="","",INDEX('01_KPI'!$O$2:$O$44,MATCH($B15,'01_KPI'!$A$2:$A$44,0))) -> > 120 j | M15: =IF($B15="","",INDEX('01_KPI'!$R$2:$R$44,MATCH($B15,'01_KPI'!$A$2:$A$44,0))) -> Mensuelle
A16: =IF($B16="","",ROW()-9) -> 7 | B16: =IFERROR(INDEX('03_Matrice_Roles'!$A$4:$A$46,MATCH(ROW()-9,'03_Matrice_Roles'!$K$4:$K$46,0)),"") -> DL2 | C16: =IF($B16="","",INDEX('01_KPI'!$C$2:$C$44,MATCH($B16,'01_KPI'!$A$2:$A$44,0))) -> Dérive de délai par avenants | D16: =IF($B16="","",INDEX('01_KPI'!$D$2:$D$44,MATCH($B16,'01_KPI'!$A$2:$A$44,0))) -> [M] | E16: =IF($B16="","",INDEX('01_KPI'!$E$2:$E$44,MATCH($B16,'01_KPI'!$A$2:$A$44,0))) -> MVP | F16: =IF($B16="","",IF(INDEX('03_Matrice_Roles'!$E$4:$J$46,MATCH($B16,'03_Matrice_Roles'!$A$4:$A$46,0),$B$4)="R","Responsable",IF(INDEX('03_Matrice_Roles'!$E$4:$J$46,MATCH($B16,'03_Matrice_Roles'!$A$4:$A$46,0),$B$4)="S","Alimente","Consulte"))) -> Consulte | G16: =IF($B16="","",INDEX('01_KPI'!$G$2:$G$44,MATCH($B16,'01_KPI'!$A$2:$A$44,0))) -> Allongement du délai par avenants par rapport au délai initial ; 1 = aucun allongement. | H16: =IF($B16="","",INDEX('01_KPI'!$I$2:$I$44,MATCH($B16,'01_KPI'!$A$2:$A$44,0))) -> ratio | I16: =IF($B16="","",INDEX('01_KPI'!$J$2:$J$44,MATCH($B16,'01_KPI'!$A$2:$A$44,0))) -> Plus bas = mieux | J16: =IF($B16="","",INDEX('01_KPI'!$M$2:$M$44,MATCH($B16,'01_KPI'!$A$2:$A$44,0))) -> ≤ 1.25 ratio | K16: =IF($B16="","",INDEX('01_KPI'!$N$2:$N$44,MATCH($B16,'01_KPI'!$A$2:$A$44,0))) -> > 1.25 à 2.0 ratio | L16: =IF($B16="","",INDEX('01_KPI'!$O$2:$O$44,MATCH($B16,'01_KPI'!$A$2:$A$44,0))) -> > 2.0 ratio | M16: =IF($B16="","",INDEX('01_KPI'!$R$2:$R$44,MATCH($B16,'01_KPI'!$A$2:$A$44,0))) -> Mensuelle
